<mujoco model="RR_Mechanism_Model_472268">
    <default>
        <joint springdamper="1 100" axis="0 1 0" limited="true" range="-90 90" />
        <geom type="capsule" size=".005" />
        <site rgba="0.5 0.5 0.5 1" />
        <default class="visual_cylinder">
            <geom type="cylinder" fromto="0 .01 0 0 -.01 0" size=".01" rgba=".5 .0 .5 .5" />
        </default>
    </default>

    <statistic center="0.065 0 0.285" extent="0.225" />

    <visual>
        <headlight diffuse="0.6 0.6 0.6" ambient="0.25 0.25 0.25" />
        <rgba haze="0.05 0.1 0.15 1" />
        <global azimuth="85" elevation="-10" />
    </visual>

    <asset>
        <texture type="skybox" builtin="gradient" rgb1="0.3 0.5 0.7" rgb2="0.1 0.2 0.3" width="512"
            height="512" />
        <texture type="2d" name="groundplane" builtin="checker" mark="edge" rgb1="0.5 0.6 0.7"
            rgb2="0.005 0.005 0.005" markrgb="0.8 0.8 0.8" width="300" height="300" />
        <material name="groundplane" texture="groundplane" texuniform="true" texrepeat="10 10"
            reflectance="0.2" />
    </asset>

    <worldbody>
        <light pos="0 0 1.5" />
        <light pos="0 0 3" dir="0 0 -1" directional="true" />
        <geom name="floor" size="0 0 .125" type="plane" material="groundplane" conaffinity="15"
            condim="3" />

        <body pos="0 0 .3">
            <geom name='left_wall' type="box" size="0.003 0.04 0.02"
                rgba="0.35 0.35 0.35 1" pos=" -0.003 0 0" />
            <geom fromto="0 0 0 .045 0 0" contype="0" conaffinity="0" density="5000" />
            <site name="s1" pos="0 0 0.015" size=".004" rgba="0 0 0 1" />
            <site name="s2" pos="0 0 -0.015" size=".004" rgba="0 0 0 1" />
            <body pos=".045 0 0">
                <joint name="one" axis="0 1 0" />
                <geom fromto="0 0 0 .039 0 0" density="5000" />
                <geom name="Pulley1" type="cylinder" fromto="0 .01 0 0 -.01 0" size=".01"
                    rgba=".5 .0 .5 .6" />
                <site name="s3" pos="0 0 0.012" size=".004" rgba="0 0 0 1" />
                <site name="s4" pos="0 0 -0.012" size=".004" rgba="0 0 0 1" />

                <site name="c1" pos=".02 0 0" size=".004" rgba="0.5 0.5 0.5 1" />

                <body pos=".039 0 0">
                    <joint name="two" />
                    <geom name="Pulley2" type="cylinder" fromto="0 .01 0 0 -.01 0" size=".01"
                        rgba=".5 .0 .5 .6" />
                    <site name="s5" pos="0 0 -0.012" size=".004" rgba="0 0 0 1" />
                    <site name="s6" pos="0 0 0.012" size=".004" rgba="0 0 0 1" />
                    <geom fromto="0 0 0 .055 0 0" density="5000" />
                    <site name="s7" pos=".055 0 0.015" size=".004" rgba="0 0 0 1" />
                    <site name="s8" pos=".055 0 -0.015" size=".004" rgba="0 0 0 1" />
                    <body>
                        <geom name='right_wall' type="box" size="0.001 0.02 0.0175"
                            rgba="0.35 0.35 0.35 1" pos=" 0.056 0 0" />
                    </body>
                </body>
            </body>
        </body>
    </worldbody>

    <tendon>
        <spatial stiffness="10" rgba="1 0 0 1">
            <site site="s1" />
            <geom geom="Pulley1" sidesite="s3" />
            <site site="c1" />
            <geom geom="Pulley2" sidesite="s5" />
            <site site="s8" />
        </spatial>
        <spatial stiffness="10" rgba="0 1 0 1">
            <site site="s2" />
            <geom geom="Pulley1" sidesite="s4" />
            <site site="c1" />
            <geom geom="Pulley2" sidesite="s6" />
            <site site="s7" />
        </spatial>
    </tendon>

</mujoco>